Workbook

Sheet 인물소개
A1: PICKA 페르소나 인물 소개
A3: 구분 | B3: 김서연 | C3: 박준혁 | D3: 이지훈 | E3: 정은주
A4: ID | B4: persona1 | C4: persona2 | D4: persona3 | E4: persona4
A5: 이름 | B5: 김서연 | C5: 박준혁 | D5: 이지훈 | E5: 정은주
A6: 나이/성별 | B6: 24세 여성 | C6: 30세 남성 | D6: 36세 남성 | E6: 45세 여성
A7: 직업 | B7: 대학생 | C7: IT 기업 개발자 | D7: 직장인 | E7: 전업주부
A8: 거주지 | B8: 서울 마포구 | C8: 경기도 성남시 | D8: 경기도 수원시 | E8: 서울 양천구
A9: 자녀 | B9: 없음 | C9: 없음 | D9: 1명 · 영아 (만 0세 11개월 0일) | E9: 2명 · 고등학생 (만 16세 8개월 6일), 중학생 (만 13세 4개월 17일)
A10: 한 줄 소개 | B10: 자기관리와 여행을 즐기는 합리적 소비자 | C10: 실용적 소비를 추구하는 차량 보유자 | D10: 11개월 아기 양육 중, 가족 중심의 소비 | E10: 자녀 2명(중/고등학생), 교육비와 생활비 관리 중심
A11: 월 예산(원) | B11: 1000000 | C11: 1200000 | D11: 3000000 | E11: 4500000
A12: 기록 기간 | B12: 2026-05~2026-07 | C12: 2026-05~2026-07 | D12: 2026-05~2026-07 | E12: 2026-05~2026-07
A13: 통신사 | B13: KT | C13: SKT | D13: KT | E13: LGU+
A14: 주 이동수단 | B14: 대중교통 (K-패스) | C14: 자가용 (하이패스) | D14: 자가용 (하이패스) | E14: 자가용 (하이패스)
A15: 주 쇼핑 제휴 | B15: 해당 없음 | C15: 이마트 | D15: 이마트 | E15: 롯데
A16: 멤버십 | B16: 스타벅스 리워드, CJ ONE, 대한항공 SKYPASS, 네이버플러스 멤버십, 신세계포인트 | C16: T 멤버십, GS&POINT, MY S-OIL, 네이버플러스 멤버십, 현대자동차 블루멤버스 | D16: 쿠팡 와우 멤버십, 신세계포인트, CJ ONE, 해피포인트, LG U+ 멤버십 | E16: L.POINT, 신세계포인트, CJ ONE, 해피포인트, T 멤버십, 교보문고 회원
A17: 보유 카드 수 | B17: 3 | C17: 2 | D17: 3 | E17: 6
A18: 보유 카드 | B18: 노리2 체크카드(Global) 청춘대로 톡톡카드 디지로카 Travel | C18: 밸런스 카드 신한카드 Deep Oil | D18: 노리2 체크카드(Global) 신한카드 Mr.Life 국민행복 삼성카드 V2 | E18: KB YOU Prime 카드 I’m GREAT LOCA 365 카드 삼성 iD EDU 카드 신한카드 Mr.Life DA@카드의정석
A19: 카드별 역할 | B19: 노리2 체크카드(Global):생활·편의점·배달·문화 청춘대로 톡톡카드:카페·교통·간편결제 디지로카 Travel:국내여행·일반적립 | C19: 밸런스 카드:운동·배달·대중교통·구독·편의점 신한카드 Deep Oil:주유·주차·택시 | D19: 노리2 체크카드(Global):구독·배달·소액생활 신한카드 Mr.Life:외식·온라인쇼핑·병원/약국 국민행복 삼성카드 V2:육아·마트·보험·병원·관리비·통신 | E19: KB YOU Prime 카드:대형마트·카페·가족생활 I’m GREAT:병원·약국·보험 LOCA 365 카드:통신·구독 삼성 iD EDU 카드:학원비·교재·교육 신한카드 Mr.Life:온라인장보기·쇼핑·외식 DA@카드의정석:혜택 공백 일반결제
A20: 선호 혜택 | B20: 온라인쇼핑·배달앱·카페 적립률 높은 카드, 대중교통 할인, 영화 할인 혜택 | C20: 주유 할인, 대중교통·택시 적립, 헬스장/PT 할인, 배달앱 캐시백 카드 | D20: 가족 공동카드는 육아·마트·병원·보험·공과금에, 개인카드는 구독·배달·외식 등에 구분해 혜택 비교 | E20: 학원비 자동이체 할인, 대형마트·쿠팡·컬리 적립, 병원·약국 할인, 통신비 캐시백 카드

Sheet 소비성향
A1: 페르소나별 소비 성향 요약 (2026-05 ~ 2026-07)
A3: 지표 | B3: 김서연 | C3: 박준혁 | D3: 이지훈 | E3: 정은주
A4: 3개월 총결제(원) | B4: =SUMIF(거래데이터!$A$2:$A$457,"persona1",거래데이터!$G$2:$G$457) -> 3486600 | C4: =SUMIF(거래데이터!$A$2:$A$457,"persona2",거래데이터!$G$2:$G$457) -> 3297700 | D4: =SUMIF(거래데이터!$A$2:$A$457,"persona3",거래데이터!$G$2:$G$457) -> 8652400 | E4: =SUMIF(거래데이터!$A$2:$A$457,"persona4",거래데이터!$G$2:$G$457) -> 13500000
A5: 결제 건수 | B5: =COUNTIF(거래데이터!$A$2:$A$457,"persona1") -> 120 | C5: =COUNTIF(거래데이터!$A$2:$A$457,"persona2") -> 107 | D5: =COUNTIF(거래데이터!$A$2:$A$457,"persona3") -> 98 | E5: =COUNTIF(거래데이터!$A$2:$A$457,"persona4") -> 131
A6: 건당 평균(원) | B6: =ROUND(B4/B5,0) -> 29055 | C6: =ROUND(C4/C5,0) -> 30820 | D6: =ROUND(D4/D5,0) -> 88290 | E6: =ROUND(E4/E5,0) -> 103053
A7: 월평균 지출(원) | B7: =ROUND(B4/3,0) -> 1162200 | C7: =ROUND(C4/3,0) -> 1099233 | D7: =ROUND(D4/3,0) -> 2884133 | E7: =ROUND(E4/3,0) -> 4500000
A8: 월 예산(원) | B8: 1000000 | C8: 1200000 | D8: 3000000 | E8: 4500000
A9: 예산 대비 집행률 | B9: =B7/B8 -> 1.1622 | C9: =C7/C8 -> 0.9160275 | D9: =D7/D8 -> 0.96137767 | E9: =E7/E8 -> 1
A10: 2026-05 지출(원) | B10: =SUMIFS(거래데이터!$G$2:$G$457,거래데이터!$A$2:$A$457,"persona1",거래데이터!$C$2:$C$457,"2026-05") -> 1127300 | C10: =SUMIFS(거래데이터!$G$2:$G$457,거래데이터!$A$2:$A$457,"persona2",거래데이터!$C$2:$C$457,"2026-05") -> 1077200 | D10: =SUMIFS(거래데이터!$G$2:$G$457,거래데이터!$A$2:$A$457,"persona3",거래데이터!$C$2:$C$457,"2026-05") -> 2855300 | E10: =SUMIFS(거래데이터!$G$2:$G$457,거래데이터!$A$2:$A$457,"persona4",거래데이터!$C$2:$C$457,"2026-05") -> 4350000
A11: 2026-06 지출(원) | B11: =SUMIFS(거래데이터!$G$2:$G$457,거래데이터!$A$2:$A$457,"persona1",거래데이터!$C$2:$C$457,"2026-06") -> 1185400 | C11: =SUMIFS(거래데이터!$G$2:$G$457,거래데이터!$A$2:$A$457,"persona2",거래데이터!$C$2:$C$457,"2026-06") -> 1110200 | D11: =SUMIFS(거래데이터!$G$2:$G$457,거래데이터!$A$2:$A$457,"persona3",거래데이터!$C$2:$C$457,"2026-06") -> 2884100 | E11: =SUMIFS(거래데이터!$G$2:$G$457,거래데이터!$A$2:$A$457,"persona4",거래데이터!$C$2:$C$457,"2026-06") -> 4500000
A12: 2026-07 지출(원) | B12: =SUMIFS(거래데이터!$G$2:$G$457,거래데이터!$A$2:$A$457,"persona1",거래데이터!$C$2:$C$457,"2026-07") -> 1173900 | C12: =SUMIFS(거래데이터!$G$2:$G$457,거래데이터!$A$2:$A$457,"persona2",거래데이터!$C$2:$C$457,"2026-07") -> 1110300 | D12: =SUMIFS(거래데이터!$G$2:$G$457,거래데이터!$A$2:$A$457,"persona3",거래데이터!$C$2:$C$457,"2026-07") -> 2913000 | E12: =SUMIFS(거래데이터!$G$2:$G$457,거래데이터!$A$2:$A$457,"persona4",거래데이터!$C$2:$C$457,"2026-07") -> 4650000
A13: 지출 1위 | B13: 백화점 (15.7%) | C13: 주유 (21.4%) | D13: 마트/쇼핑 (19.3%) | E13: 교육/육아 (28.8%)
A14: 지출 2위 | B14: 외식 (11.1%) | C14: 외식 (11.0%) | D14: 교육/육아 (18.3%) | E14: 마트/쇼핑 (18.3%)
A15: 지출 3위 | B15: 여행/숙박 (6.9%) | C15: 항공 (7.3%) | D15: 항공 (15.3%) | E15: 공과금 (10.2%)
A16: 결제수단 (신용/체크) | B16: =COUNTIFS(거래데이터!$A$2:$A$457,"persona1",거래데이터!$J$2:$J$457,"신용카드")&" / "&COUNTIFS(거래데이터!$A$2:$A$457,"persona1",거래데이터!$J$2:$J$457,"체크카드") -> 89 / 31 | C16: =COUNTIFS(거래데이터!$A$2:$A$457,"persona2",거래데이터!$J$2:$J$457,"신용카드")&" / "&COUNTIFS(거래데이터!$A$2:$A$457,"persona2",거래데이터!$J$2:$J$457,"체크카드") -> 107 / 0 | D16: =COUNTIFS(거래데이터!$A$2:$A$457,"persona3",거래데이터!$J$2:$J$457,"신용카드")&" / "&COUNTIFS(거래데이터!$A$2:$A$457,"persona3",거래데이터!$J$2:$J$457,"체크카드") -> 77 / 20 | E16: =COUNTIFS(거래데이터!$A$2:$A$457,"persona4",거래데이터!$J$2:$J$457,"신용카드")&" / "&COUNTIFS(거래데이터!$A$2:$A$457,"persona4",거래데이터!$J$2:$J$457,"체크카드") -> 131 / 0
A17: 소비 패턴 | B17: 소액 다빈도형. 카페·교통 결제가 잦고 가끔 대형 지출이 튐 (롯데백화점 54.6만 원 1건) | C17: 차량 중심 고정지출형. 주유 14건이 최대 비중, 나머지는 외식·구독 위주 | D17: 육아·마트 정기지출 + 대형 이벤트성 결제 (가족 항공권 108만 원) | E17: 고정비 집중형. 학원비·교재비가 매달 반복되고 예산과 지출이 거의 일치
A18: 주요 가맹점 | B18: 스타벅스, 티머니, 카카오 T, 한식당 | C18: SK에너지 주유소, 한식당, 스타벅스, 김밥전문점 | D18: 이마트, 홈플러스, 아이사랑몰, 한식당 | E18: 이마트, 중등 영어학원, 홈플러스, 고등 수학학원
A19: 실수령 혜택(원) | B19: =SUMIF(거래데이터!$A$2:$A$457,"persona1",거래데이터!$N$2:$N$457) -> 43000 | C19: =SUMIF(거래데이터!$A$2:$A$457,"persona2",거래데이터!$N$2:$N$457) -> 47300 | D19: =SUMIF(거래데이터!$A$2:$A$457,"persona3",거래데이터!$N$2:$N$457) -> 121200 | E19: =SUMIF(거래데이터!$A$2:$A$457,"persona4",거래데이터!$N$2:$N$457) -> 140100
A20: 잠재 혜택(원) | B20: =SUMIF(거래데이터!$A$2:$A$457,"persona1",거래데이터!$O$2:$O$457) -> 105800 | C20: =SUMIF(거래데이터!$A$2:$A$457,"persona2",거래데이터!$O$2:$O$457) -> 102300 | D20: =SUMIF(거래데이터!$A$2:$A$457,"persona3",거래데이터!$O$2:$O$457) -> 276900 | E20: =SUMIF(거래데이터!$A$2:$A$457,"persona4",거래데이터!$O$2:$O$457) -> 292900
A21: 놓친 혜택(원) | B21: =SUMIF(거래데이터!$A$2:$A$457,"persona1",거래데이터!$P$2:$P$457) -> 62800 | C21: =SUMIF(거래데이터!$A$2:$A$457,"persona2",거래데이터!$P$2:$P$457) -> 55000 | D21: =SUMIF(거래데이터!$A$2:$A$457,"persona3",거래데이터!$P$2:$P$457) -> 155700 | E21: =SUMIF(거래데이터!$A$2:$A$457,"persona4",거래데이터!$P$2:$P$457) -> 152800
A22: 혜택 손실률 | B22: =B21/B20 -> 0.59357278 | C22: =C21/C20 -> 0.53763441 | D22: =D21/D20 -> 0.56229686 | E22: =E21/E20 -> 0.52167975
A23: 카드 오선택 건수 | B23: =COUNTIFS(거래데이터!$A$2:$A$457,"persona1",거래데이터!$M$2:$M$457,"WRONG_CARD_BEFORE_PICKA") -> 46 | C23: =COUNTIFS(거래데이터!$A$2:$A$457,"persona2",거래데이터!$M$2:$M$457,"WRONG_CARD_BEFORE_PICKA") -> 25 | D23: =COUNTIFS(거래데이터!$A$2:$A$457,"persona3",거래데이터!$M$2:$M$457,"WRONG_CARD_BEFORE_PICKA") -> 45 | E23: =COUNTIFS(거래데이터!$A$2:$A$457,"persona4",거래데이터!$M$2:$M$457,"WRONG_CARD_BEFORE_PICKA") -> 72
A24: 한도 소진 건수 | B24: =COUNTIFS(거래데이터!$A$2:$A$457,"persona1",거래데이터!$M$2:$M$457,"CAP_EXHAUSTED") -> 45 | C24: =COUNTIFS(거래데이터!$A$2:$A$457,"persona2",거래데이터!$M$2:$M$457,"CAP_EXHAUSTED") -> 61 | D24: =COUNTIFS(거래데이터!$A$2:$A$457,"persona3",거래데이터!$M$2:$M$457,"CAP_EXHAUSTED") -> 37 | E24: =COUNTIFS(거래데이터!$A$2:$A$457,"persona4",거래데이터!$M$2:$M$457,"CAP_EXHAUSTED") -> 18
A25: 혜택 정상 수령 건수 | B25: =COUNTIFS(거래데이터!$A$2:$A$457,"persona1",거래데이터!$M$2:$M$457,"BENEFIT_RECEIVED") -> 23 | C25: =COUNTIFS(거래데이터!$A$2:$A$457,"persona2",거래데이터!$M$2:$M$457,"BENEFIT_RECEIVED") -> 19 | D25: =COUNTIFS(거래데이터!$A$2:$A$457,"persona3",거래데이터!$M$2:$M$457,"BENEFIT_RECEIVED") -> 15 | E25: =COUNTIFS(거래데이터!$A$2:$A$457,"persona4",거래데이터!$M$2:$M$457,"BENEFIT_RECEIVED") -> 41
A26: 적용 혜택 없음 건수 | B26: =COUNTIFS(거래데이터!$A$2:$A$457,"persona1",거래데이터!$M$2:$M$457,"NO_ELIGIBLE_BENEFIT") -> 6 | C26: =COUNTIFS(거래데이터!$A$2:$A$457,"persona2",거래데이터!$M$2:$M$457,"NO_ELIGIBLE_BENEFIT") -> 2 | D26: =COUNTIFS(거래데이터!$A$2:$A$457,"persona3",거래데이터!$M$2:$M$457,"NO_ELIGIBLE_BENEFIT") -> 1 | E26: =COUNTIFS(거래데이터!$A$2:$A$457,"persona4",거래데이터!$M$2:$M$457,"NO_ELIGIBLE_BENEFIT") -> 0
A27: 핵심 진단 | B27: 체크·신용 혼용으로 혜택 분산. 잘못된 카드 선택과 한도 소진이 비슷한 비중 | C27: 카드 2장으로 커버 한계 → 한도 소진이 최대 손실 원인 (61건) | D27: 카드 3장 역할 분리는 되어 있으나 실제 결제 시 오선택 45건 | E27: 카드 6장 보유에도 오선택 72건 — 선택 실패가 압도적 손실 원인
A29: ※ 모든 수치는 [거래데이터] 시트의 456건 원본 거래를 SUMIFS/COUNTIFS로 집계한 값입니다. 지출 순위·소비 패턴·핵심 진단은 집계 결과를 바탕으로 작성한 해석 텍스트입니다.

Sheet 카테고리별지출
A1: 카테고리별 지출 비교
A3: 카테고리 | B3: 김서연 금액 | C3: 박준혁 금액 | D3: 이지훈 금액 | E3: 정은주 금액 | F3: 김서연 비중 | G3: 박준혁 비중 | H3: 이지훈 비중 | I3: 정은주 비중 | J3: 합계
A4: 교육/육아 | B4: =SUMIFS(거래데이터!$G$2:$G$457,거래데이터!$A$2:$A$457,"persona1",거래데이터!$F$2:$F$457,$A4) -> 78400 | C4: =SUMIFS(거래데이터!$G$2:$G$457,거래데이터!$A$2:$A$457,"persona2",거래데이터!$F$2:$F$457,$A4) -> 95100 | D4: =SUMIFS(거래데이터!$G$2:$G$457,거래데이터!$A$2:$A$457,"persona3",거래데이터!$F$2:$F$457,$A4) -> 1581100 | E4: =SUMIFS(거래데이터!$G$2:$G$457,거래데이터!$A$2:$A$457,"persona4",거래데이터!$F$2:$F$457,$A4) -> 3889700 | F4: =IFERROR(B4/B$32,0) -> 0.02248609 | G4: =IFERROR(C4/C$32,0) -> 0.028838281 | H4: =IFERROR(D4/D$32,0) -> 0.18273543 | I4: =IFERROR(E4/E$32,0) -> 0.28812593 | J4: =SUM(B4:E4) -> 5644300
A5: 마트/쇼핑 | B5: =SUMIFS(거래데이터!$G$2:$G$457,거래데이터!$A$2:$A$457,"persona1",거래데이터!$F$2:$F$457,$A5) -> 153000 | C5: =SUMIFS(거래데이터!$G$2:$G$457,거래데이터!$A$2:$A$457,"persona2",거래데이터!$F$2:$F$457,$A5) -> 236100 | D5: =SUMIFS(거래데이터!$G$2:$G$457,거래데이터!$A$2:$A$457,"persona3",거래데이터!$F$2:$F$457,$A5) -> 1667400 | E5: =SUMIFS(거래데이터!$G$2:$G$457,거래데이터!$A$2:$A$457,"persona4",거래데이터!$F$2:$F$457,$A5) -> 2476900 | F5: =IFERROR(B5/B$32,0) -> 0.043882292 | G5: =IFERROR(C5/C$32,0) -> 0.071595354 | H5: =IFERROR(D5/D$32,0) -> 0.19270954 | I5: =IFERROR(E5/E$32,0) -> 0.18347407 | J5: =SUM(B5:E5) -> 4533400
A6: 공과금 | B6: =SUMIFS(거래데이터!$G$2:$G$457,거래데이터!$A$2:$A$457,"persona1",거래데이터!$F$2:$F$457,$A6) -> 191300 | C6: =SUMIFS(거래데이터!$G$2:$G$457,거래데이터!$A$2:$A$457,"persona2",거래데이터!$F$2:$F$457,$A6) -> 159000 | D6: =SUMIFS(거래데이터!$G$2:$G$457,거래데이터!$A$2:$A$457,"persona3",거래데이터!$F$2:$F$457,$A6) -> 939900 | E6: =SUMIFS(거래데이터!$G$2:$G$457,거래데이터!$A$2:$A$457,"persona4",거래데이터!$F$2:$F$457,$A6) -> 1375400 | F6: =IFERROR(B6/B$32,0) -> 0.054867206 | G6: =IFERROR(C6/C$32,0) -> 0.048215423 | H6: =IFERROR(D6/D$32,0) -> 0.10862882 | I6: =IFERROR(E6/E$32,0) -> 0.10188148 | J6: =SUM(B6:E6) -> 2665600
A7: 주유 | B7: =SUMIFS(거래데이터!$G$2:$G$457,거래데이터!$A$2:$A$457,"persona1",거래데이터!$F$2:$F$457,$A7) -> 24300 | C7: =SUMIFS(거래데이터!$G$2:$G$457,거래데이터!$A$2:$A$457,"persona2",거래데이터!$F$2:$F$457,$A7) -> 704400 | D7: =SUMIFS(거래데이터!$G$2:$G$457,거래데이터!$A$2:$A$457,"persona3",거래데이터!$F$2:$F$457,$A7) -> 498600 | E7: =SUMIFS(거래데이터!$G$2:$G$457,거래데이터!$A$2:$A$457,"persona4",거래데이터!$F$2:$F$457,$A7) -> 615800 | F7: =IFERROR(B7/B$32,0) -> 0.0069695405 | G7: =IFERROR(C7/C$32,0) -> 0.21360342 | H7: =IFERROR(D7/D$32,0) -> 0.05762563 | I7: =IFERROR(E7/E$32,0) -> 0.045614815 | J7: =SUM(B7:E7) -> 1843100
A8: 항공 | B8: =SUMIFS(거래데이터!$G$2:$G$457,거래데이터!$A$2:$A$457,"persona1",거래데이터!$F$2:$F$457,$A8) -> 72900 | C8: =SUMIFS(거래데이터!$G$2:$G$457,거래데이터!$A$2:$A$457,"persona2",거래데이터!$F$2:$F$457,$A8) -> 241000 | D8: =SUMIFS(거래데이터!$G$2:$G$457,거래데이터!$A$2:$A$457,"persona3",거래데이터!$F$2:$F$457,$A8) -> 1326900 | E8: =SUMIFS(거래데이터!$G$2:$G$457,거래데이터!$A$2:$A$457,"persona4",거래데이터!$F$2:$F$457,$A8) -> 156900 | F8: =IFERROR(B8/B$32,0) -> 0.020908622 | G8: =IFERROR(C8/C$32,0) -> 0.073081238 | H8: =IFERROR(D8/D$32,0) -> 0.15335629 | I8: =IFERROR(E8/E$32,0) -> 0.011622222 | J8: =SUM(B8:E8) -> 1797700
A9: 외식 | B9: =SUMIFS(거래데이터!$G$2:$G$457,거래데이터!$A$2:$A$457,"persona1",거래데이터!$F$2:$F$457,$A9) -> 387800 | C9: =SUMIFS(거래데이터!$G$2:$G$457,거래데이터!$A$2:$A$457,"persona2",거래데이터!$F$2:$F$457,$A9) -> 364100 | D9: =SUMIFS(거래데이터!$G$2:$G$457,거래데이터!$A$2:$A$457,"persona3",거래데이터!$F$2:$F$457,$A9) -> 227200 | E9: =SUMIFS(거래데이터!$G$2:$G$457,거래데이터!$A$2:$A$457,"persona4",거래데이터!$F$2:$F$457,$A9) -> 411700 | F9: =IFERROR(B9/B$32,0) -> 0.11122584 | G9: =IFERROR(C9/C$32,0) -> 0.11041029 | H9: =IFERROR(D9/D$32,0) -> 0.02625861 | I9: =IFERROR(E9/E$32,0) -> 0.030496296 | J9: =SUM(B9:E9) -> 1390800
A10: 생활 | B10: =SUMIFS(거래데이터!$G$2:$G$457,거래데이터!$A$2:$A$457,"persona1",거래데이터!$F$2:$F$457,$A10) -> 140000 | C10: =SUMIFS(거래데이터!$G$2:$G$457,거래데이터!$A$2:$A$457,"persona2",거래데이터!$F$2:$F$457,$A10) -> 108800 | D10: =SUMIFS(거래데이터!$G$2:$G$457,거래데이터!$A$2:$A$457,"persona3",거래데이터!$F$2:$F$457,$A10) -> 247200 | E10: =SUMIFS(거래데이터!$G$2:$G$457,거래데이터!$A$2:$A$457,"persona4",거래데이터!$F$2:$F$457,$A10) -> 699900 | F10: =IFERROR(B10/B$32,0) -> 0.040153731 | G10: =IFERROR(C10/C$32,0) -> 0.032992692 | H10: =IFERROR(D10/D$32,0) -> 0.028570108 | I10: =IFERROR(E10/E$32,0) -> 0.051844444 | J10: =SUM(B10:E10) -> 1195900
A11: 백화점 | B11: =SUMIFS(거래데이터!$G$2:$G$457,거래데이터!$A$2:$A$457,"persona1",거래데이터!$F$2:$F$457,$A11) -> 545700 | C11: =SUMIFS(거래데이터!$G$2:$G$457,거래데이터!$A$2:$A$457,"persona2",거래데이터!$F$2:$F$457,$A11) -> 34600 | D11: =SUMIFS(거래데이터!$G$2:$G$457,거래데이터!$A$2:$A$457,"persona3",거래데이터!$F$2:$F$457,$A11) -> 218400 | E11: =SUMIFS(거래데이터!$G$2:$G$457,거래데이터!$A$2:$A$457,"persona4",거래데이터!$F$2:$F$457,$A11) -> 264400 | F11: =IFERROR(B11/B$32,0) -> 0.15651351 | G11: =IFERROR(C11/C$32,0) -> 0.010492161 | H11: =IFERROR(D11/D$32,0) -> 0.025241551 | I11: =IFERROR(E11/E$32,0) -> 0.019585185 | J11: =SUM(B11:E11) -> 1063100
A12: 온라인쇼핑 | B12: =SUMIFS(거래데이터!$G$2:$G$457,거래데이터!$A$2:$A$457,"persona1",거래데이터!$F$2:$F$457,$A12) -> 138200 | C12: =SUMIFS(거래데이터!$G$2:$G$457,거래데이터!$A$2:$A$457,"persona2",거래데이터!$F$2:$F$457,$A12) -> 28500 | D12: =SUMIFS(거래데이터!$G$2:$G$457,거래데이터!$A$2:$A$457,"persona3",거래데이터!$F$2:$F$457,$A12) -> 63200 | E12: =SUMIFS(거래데이터!$G$2:$G$457,거래데이터!$A$2:$A$457,"persona4",거래데이터!$F$2:$F$457,$A12) -> 763300 | F12: =IFERROR(B12/B$32,0) -> 0.039637469 | G12: =IFERROR(C12/C$32,0) -> 0.0086423871 | H12: =IFERROR(D12/D$32,0) -> 0.0073043317 | I12: =IFERROR(E12/E$32,0) -> 0.056540741 | J12: =SUM(B12:E12) -> 993200
A13: 여행/숙박 | B13: =SUMIFS(거래데이터!$G$2:$G$457,거래데이터!$A$2:$A$457,"persona1",거래데이터!$F$2:$F$457,$A13) -> 241500 | C13: =SUMIFS(거래데이터!$G$2:$G$457,거래데이터!$A$2:$A$457,"persona2",거래데이터!$F$2:$F$457,$A13) -> 167600 | D13: =SUMIFS(거래데이터!$G$2:$G$457,거래데이터!$A$2:$A$457,"persona3",거래데이터!$F$2:$F$457,$A13) -> 212800 | E13: =SUMIFS(거래데이터!$G$2:$G$457,거래데이터!$A$2:$A$457,"persona4",거래데이터!$F$2:$F$457,$A13) -> 247300 | F13: =IFERROR(B13/B$32,0) -> 0.069265187 | G13: =IFERROR(C13/C$32,0) -> 0.050823301 | H13: =IFERROR(D13/D$32,0) -> 0.024594332 | I13: =IFERROR(E13/E$32,0) -> 0.018318519 | J13: =SUM(B13:E13) -> 869200
A14: 통신 | B14: =SUMIFS(거래데이터!$G$2:$G$457,거래데이터!$A$2:$A$457,"persona1",거래데이터!$F$2:$F$457,$A14) -> 146600 | C14: =SUMIFS(거래데이터!$G$2:$G$457,거래데이터!$A$2:$A$457,"persona2",거래데이터!$F$2:$F$457,$A14) -> 180700 | D14: =SUMIFS(거래데이터!$G$2:$G$457,거래데이터!$A$2:$A$457,"persona3",거래데이터!$F$2:$F$457,$A14) -> 210100 | E14: =SUMIFS(거래데이터!$G$2:$G$457,거래데이터!$A$2:$A$457,"persona4",거래데이터!$F$2:$F$457,$A14) -> 289800 | F14: =IFERROR(B14/B$32,0) -> 0.042046693 | G14: =IFERROR(C14/C$32,0) -> 0.054795767 | H14: =IFERROR(D14/D$32,0) -> 0.02428228 | I14: =IFERROR(E14/E$32,0) -> 0.021466667 | J14: =SUM(B14:E14) -> 827200
A15: 의료 | B15: =SUMIFS(거래데이터!$G$2:$G$457,거래데이터!$A$2:$A$457,"persona1",거래데이터!$F$2:$F$457,$A15) -> 43600 | C15: =SUMIFS(거래데이터!$G$2:$G$457,거래데이터!$A$2:$A$457,"persona2",거래데이터!$F$2:$F$457,$A15) -> 16100 | D15: =SUMIFS(거래데이터!$G$2:$G$457,거래데이터!$A$2:$A$457,"persona3",거래데이터!$F$2:$F$457,$A15) -> 258300 | E15: =SUMIFS(거래데이터!$G$2:$G$457,거래데이터!$A$2:$A$457,"persona4",거래데이터!$F$2:$F$457,$A15) -> 478100 | F15: =IFERROR(B15/B$32,0) -> 0.012505019 | G15: =IFERROR(C15/C$32,0) -> 0.0048821906 | H15: =IFERROR(D15/D$32,0) -> 0.029852989 | I15: =IFERROR(E15/E$32,0) -> 0.035414815 | J15: =SUM(B15:E15) -> 796100
... A31: 멤버십 | B31: =SUMIFS(거래데이터!$G$2:$G$457,거래데이터!$A$2:$A$457,"persona1",거래데이터!$F$2:$F$457,$A31) -> 6600 | C31: =SUMIFS(거래데이터!$G$2:$G$457,거래데이터!$A$2:$A$457,"persona2",거래데이터!$F$2:$F$457,$A31) -> 7900 | D31: =SUMIFS(거래데이터!$G$2:$G$457,거래데이터!$A$2:$A$457,"persona3",거래데이터!$F$2:$F$457,$A31) -> 19500 | E31: =SUMIFS(거래데이터!$G$2:$G$457,거래데이터!$A$2:$A$457,"persona4",거래데이터!$F$2:$F$457,$A31) -> 8700 | F31: =IFERROR(B31/B$32,0) -> 0.0018929616 | G31: =IFERROR(C31/C$32,0) -> 0.0023956091 | H31: =IFERROR(D31/D$32,0) -> 0.00225371 | I31: =IFERROR(E31/E$32,0) -> 0.00064444444 | J31: =SUM(B31:E31) -> 42700
A32: 합계 | B32: =SUM(B4:B31) -> 3486600 | C32: =SUM(C4:C31) -> 3297700 | D32: =SUM(D4:D31) -> 8652400 | E32: =SUM(E4:E31) -> 13500000 | F32: =SUM(F4:F31) -> 1 | G32: =SUM(G4:G31) -> 1 | H32: =SUM(H4:H31) -> 1 | I32: =SUM(I4:I31) -> 1 | J32: =SUM(B32:E32) -> 28936700
A34: ※ 금액이 0인 카테고리는 "-"로 표시됩니다. 비중은 각 페르소나의 3개월 총결제액 대비 비율입니다.

Sheet 거래데이터
A1: 페르소나ID | B1: 이름 | C1: 이용월 | D1: 승인일시 | E1: 가맹점 | F1: 카테고리 | G1: 결제금액 | H1: 할인적용액 | I1: 최종승인액 | J1: 결제수단 | K1: 실제사용카드 | L1: 추천카드 | M1: 혜택시나리오 | N1: 실수령혜택 | O1: 잠재혜택 | P1: 놓친혜택 | Q1: 놓친사유
A2: persona1 | B2: 김서연 | C2: 2026-05 | D2: 2026-05-02T09:10:00 | E2: 쿠팡 | F2: 온라인쇼핑 | G2: 58900 | H2: 0 | I2: 58900 | J2: 체크카드 | K2: 노리2 체크카드(Global) | L2: 청춘대로 톡톡카드 | M2: WRONG_CARD_BEFORE_PICKA | N2: 0 | O2: 1400 | P2: 1400 | Q2: 픽카 이용 전 다른 카드를 사용하여 받을 수 있었던 혜택을 놓침
A3: persona1 | B3: 김서연 | C3: 2026-05 | D3: 2026-05-02T09:10:00 | E3: 클래스101 마케팅 강의 | F3: 교육/육아 | G3: 78400 | H3: 0 | I3: 78400 | J3: 신용카드 | K3: 청춘대로 톡톡카드 | L3: 청춘대로 톡톡카드 | M3: CAP_EXHAUSTED | N3: 0 | O3: 2000 | P3: 2000 | Q3: 해당 카드의 월 할인 한도가 이미 소진되어 추가 할인을 받지 못함
A4: persona1 | B4: 김서연 | C4: 2026-05 | D4: 2026-05-02T09:10:00 | E4: 스타벅스 | F4: 카페/디저트 | G4: 20500 | H4: 0 | I4: 20500 | J4: 신용카드 | K4: 디지로카 Travel | L4: 노리2 체크카드(Global) | M4: WRONG_CARD_BEFORE_PICKA | N4: 0 | O4: 500 | P4: 500 | Q4: 픽카 이용 전 다른 카드를 사용하여 받을 수 있었던 혜택을 놓침
A5: persona1 | B5: 김서연 | C5: 2026-05 | D5: 2026-05-05T12:40:00 | E5: 배달의민족 | F5: 배달앱 | G5: 46200 | H5: 2400 | I5: 43800 | J5: 체크카드 | K5: 노리2 체크카드(Global) | L5: 노리2 체크카드(Global) | M5: BENEFIT_RECEIVED | N5: 2400 | O5: 2400 | P5: 0
A6: persona1 | B6: 김서연 | C6: 2026-05 | D6: 2026-05-05T12:40:00 | E6: 네이버페이 | F6: 간편결제 | G6: 61700 | H6: 3300 | I6: 58400 | J6: 신용카드 | K6: 청춘대로 톡톡카드 | L6: 청춘대로 톡톡카드 | M6: BENEFIT_RECEIVED | N6: 3300 | O6: 3300 | P6: 0
A7: persona1 | B7: 김서연 | C7: 2026-05 | D7: 2026-05-05T12:40:00 | E7: 티머니 | F7: 교통 | G7: 16200 | H7: 0 | I7: 16200 | J7: 신용카드 | K7: 디지로카 Travel | M7: NO_ELIGIBLE_BENEFIT | N7: 0 | O7: 0 | P7: 0 | Q7: 보유 카드 중 해당 거래에 적용 가능한 확정 혜택 없음
A8: persona1 | B8: 김서연 | C8: 2026-05 | D8: 2026-05-09T18:20:00 | E8: 올리브영 | F8: 뷰티/피트니스 | G8: 67200 | H8: 0 | I8: 67200 | J8: 체크카드 | K8: 노리2 체크카드(Global) | L8: 노리2 체크카드(Global) | M8: CAP_EXHAUSTED | N8: 0 | O8: 1600 | P8: 1600 | Q8: 해당 카드의 월 할인 한도가 이미 소진되어 추가 할인을 받지 못함
A9: persona1 | B9: 김서연 | C9: 2026-05 | D9: 2026-05-09T18:20:00 | E9: 한국전력공사 | F9: 공과금 | G9: 89600 | H9: 0 | I9: 89600 | J9: 신용카드 | K9: 청춘대로 톡톡카드 | L9: 청춘대로 톡톡카드 | M9: CAP_EXHAUSTED | N9: 0 | O9: 2300 | P9: 2300 | Q9: 해당 카드의 월 할인 한도가 이미 소진되어 추가 할인을 받지 못함
A10: persona1 | B10: 김서연 | C10: 2026-05 | D10: 2026-05-09T18:20:00 | E10: 카카오 T | F10: 교통 | G10: 23500 | H10: 0 | I10: 23500 | J10: 신용카드 | K10: 디지로카 Travel | M10: NO_ELIGIBLE_BENEFIT | N10: 0 | O10: 0 | P10: 0 | Q10: 보유 카드 중 해당 거래에 적용 가능한 확정 혜택 없음
A11: persona1 | B11: 김서연 | C11: 2026-05 | D11: 2026-05-12T21:15:00 | E11: CGV | F11: 문화/영화 | G11: 37900 | H11: 0 | I11: 37900 | J11: 체크카드 | K11: 노리2 체크카드(Global) | L11: 노리2 체크카드(Global) | M11: CAP_EXHAUSTED | N11: 0 | O11: 900 | P11: 900 | Q11: 해당 카드의 월 할인 한도가 이미 소진되어 추가 할인을 받지 못함
A12: persona1 | B12: 김서연 | C12: 2026-05 | D12: 2026-05-12T21:15:00 | E12: 한식당 | F12: 외식 | G12: 50400 | H12: 0 | I12: 50400 | J12: 신용카드 | K12: 청춘대로 톡톡카드 | L12: 청춘대로 톡톡카드 | M12: CAP_EXHAUSTED | N12: 0 | O12: 1200 | P12: 1200 | Q12: 해당 카드의 월 할인 한도가 이미 소진되어 추가 할인을 받지 못함
A13: persona1 | B13: 김서연 | C13: 2026-05 | D13: 2026-05-12T21:15:00 | E13: CU | F13: 편의점 | G13: 13200 | H13: 0 | I13: 13200 | J13: 신용카드 | K13: 디지로카 Travel | L13: 노리2 체크카드(Global) | M13: WRONG_CARD_BEFORE_PICKA | N13: 0 | O13: 300 | P13: 300 | Q13: 픽카 이용 전 다른 카드를 사용하여 받을 수 있었던 혜택을 놓침
A14: persona1 | B14: 김서연 | C14: 2026-05 | D14: 2026-05-16T14:30:00 | E14: SK텔레콤 | F14: 통신 | G14: 54700 | H14: 0 | I14: 54700 | J14: 체크카드 | K14: 노리2 체크카드(Global) | L14: 청춘대로 톡톡카드 | M14: WRONG_CARD_BEFORE_PICKA | N14: 0 | O14: 1300 | P14: 1300 | Q14: 픽카 이용 전 다른 카드를 사용하여 받을 수 있었던 혜택을 놓침
A15: persona1 | B15: 김서연 | C15: 2026-05 | D15: 2026-05-16T14:30:00 | E15: 대한항공 | F15: 항공 | G15: 72900 | H15: 0 | I15: 72900 | J15: 신용카드 | K15: 청춘대로 톡톡카드 | L15: 청춘대로 톡톡카드 | M15: CAP_EXHAUSTED | N15: 0 | O15: 1800 | P15: 1800 | Q15: 해당 카드의 월 할인 한도가 이미 소진되어 추가 할인을 받지 못함
A16: persona1 | B16: 김서연 | C16: 2026-05 | D16: 2026-05-16T14:30:00 | E16: 넷플릭스 | F16: 구독/멤버십 | G16: 19000 | H16: 0 | I16: 19000 | J16: 신용카드 | K16: 디지로카 Travel | L16: 청춘대로 톡톡카드 | M16: WRONG_CARD_BEFORE_PICKA | N16: 0 | O16: 500 | P16: 500 | Q16: 픽카 이용 전 다른 카드를 사용하여 받을 수 있었던 혜택을 놓침
A17: persona1 | B17: 김서연 | C17: 2026-05 | D17: 2026-05-20T08:50:00 | E17: 다이소 | F17: 생활 | G17: 50400 | H17: 0 | I17: 50400 | J17: 체크카드 | K17: 노리2 체크카드(Global) | L17: 청춘대로 톡톡카드 | M17: WRONG_CARD_BEFORE_PICKA | N17: 0 | O17: 1200 | P17: 1200 | Q17: 픽카 이용 전 다른 카드를 사용하여 받을 수 있었던 혜택을 놓침
A18: persona1 | B18: 김서연 | C18: 2026-05 | D18: 2026-05-20T08:50:00 | E18: 카카오페이 | F18: 간편결제 | G18: 67200 | H18: 0 | I18: 67200 | J18: 신용카드 | K18: 청춘대로 톡톡카드 | L18: 청춘대로 톡톡카드 | M18: CAP_EXHAUSTED | N18: 0 | O18: 1600 | P18: 1600 | Q18: 해당 카드의 월 할인 한도가 이미 소진되어 추가 할인을 받지 못함
A19: persona1 | B19: 김서연 | C19: 2026-05 | D19: 2026-05-20T08:50:00 | E19: 서울교통공사 | F19: 교통 | G19: 17700 | H19: 0 | I19: 17700 | J19: 신용카드 | K19: 디지로카 Travel | L19: 청춘대로 톡톡카드 | M19: WRONG_CARD_BEFORE_PICKA | N19: 0 | O19: 400 | P19: 400 | Q19: 픽카 이용 전 다른 카드를 사용하여 받을 수 있었던 혜택을 놓침
A20: persona1 | B20: 김서연 | C20: 2026-05 | D20: 2026-05-24T19:05:00 | E20: 이마트 | F20: 마트/쇼핑 | G20: 63000 | H20: 3300 | I20: 59700 | J20: 체크카드 | K20: 노리2 체크카드(Global) | L20: 노리2 체크카드(Global) | M20: BENEFIT_RECEIVED | N20: 3300 | O20: 3300 | P20: 0
A21: persona1 | B21: 김서연 | C21: 2026-05 | D21: 2026-05-24T19:05:00 | E21: 김밥전문점 | F21: 외식 | G21: 84000 | H21: 4500 | I21: 79500 | J21: 신용카드 | K21: 청춘대로 톡톡카드 | L21: 청춘대로 톡톡카드 | M21: BENEFIT_RECEIVED | N21: 4500 | O21: 4500 | P21: 0
A22: persona1 | B22: 김서연 | C22: 2026-05 | D22: 2026-05-24T19:05:00 | E22: 경기버스 | F22: 교통 | G22: 22000 | H22: 0 | I22: 22000 | J22: 신용카드 | K22: 디지로카 Travel | L22: 노리2 체크카드(Global) | M22: WRONG_CARD_BEFORE_PICKA | N22: 0 | O22: 500 | P22: 500 | Q22: 픽카 이용 전 다른 카드를 사용하여 받을 수 있었던 혜택을 놓침
A23: persona1 | B23: 김서연 | C23: 2026-05 | D23: 2026-05-28T22:10:00 | E23: 이탈리안 레스토랑 | F23: 외식 | G23: 42000 | H23: 0 | I23: 42000 | J23: 체크카드 | K23: 노리2 체크카드(Global) | L23: 청춘대로 톡톡카드 | M23: WRONG_CARD_BEFORE_PICKA | N23: 0 | O23: 1000 | P23: 1000 | Q23: 픽카 이용 전 다른 카드를 사용하여 받을 수 있었던 혜택을 놓침
A24: persona1 | B24: 김서연 | C24: 2026-05 | D24: 2026-05-28T22:10:00 | E24: 메가커피 | F24: 카페/디저트 | G24: 56000 | H24: 0 | I24: 56000 | J24: 신용카드 | K24: 청춘대로 톡톡카드 | L24: 청춘대로 톡톡카드 | M24: CAP_EXHAUSTED | N24: 0 | O24: 1400 | P24: 1400 | Q24: 해당 카드의 월 할인 한도가 이미 소진되어 추가 할인을 받지 못함
A25: persona1 | B25: 김서연 | C25: 2026-05 | D25: 2026-05-28T22:10:00 | E25: 투썸플레이스 | F25: 카페/디저트 | G25: 14700 | H25: 0 | I25: 14700 | J25: 신용카드 | K25: 디지로카 Travel | L25: 청춘대로 톡톡카드 | M25: WRONG_CARD_BEFORE_PICKA | N25: 0 | O25: 400 | P25: 400 | Q25: 픽카 이용 전 다른 카드를 사용하여 받을 수 있었던 혜택을 놓침
A26: persona1 | B26: 김서연 | C26: 2026-06 | D26: 2026-06-01T08:50:00 | E26: 올리브영 | F26: 뷰티/피트니스 | G26: 9200 | H26: 0 | I26: 9200 | J26: 체크카드 | K26: 노리2 체크카드(Global) | L26: 청춘대로 톡톡카드 | M26: WRONG_CARD_BEFORE_PICKA | N26: 0 | O26: 600 | P26: 600 | Q26: 픽카 이용 전 다른 카드를 사용하여 받을 수 있었던 혜택을 놓침
A27: persona1 | B27: 김서연 | C27: 2026-06 | D27: 2026-06-01T13:05:00 | E27: 다이소 | F27: 생활 | G27: 4500 | H27: 0 | I27: 4500 | J27: 체크카드 | K27: 노리2 체크카드(Global) | L27: 청춘대로 톡톡카드 | M27: WRONG_CARD_BEFORE_PICKA | N27: 0 | O27: 300 | P27: 300 | Q27: 픽카 이용 전 다른 카드를 사용하여 받을 수 있었던 혜택을 놓침
A28: persona1 | B28: 김서연 | C28: 2026-06 | D28: 2026-06-01T14:15:00 | E28: 스타벅스 | F28: 카페/디저트 | G28: 2800 | H28: 0 | I28: 2800 | J28: 신용카드 | K28: 청춘대로 톡톡카드 | L28: 청춘대로 톡톡카드 | M28: CAP_EXHAUSTED | N28: 0 | O28: 200 | P28: 200 | Q28: 해당 카드의 월 할인 한도가 이미 소진되어 추가 할인을 받지 못함
A29: persona1 | B29: 김서연 | C29: 2026-06 | D29: 2026-06-02T10:15:00 | E29: 롯데백화점 | F29: 백화점 | G29: 545700 | H29: 0 | I29: 545700 | J29: 체크카드 | K29: 노리2 체크카드(Global) | M29: NO_ELIGIBLE_BENEFIT | N29: 0 | O29: 0 | P29: 0 | Q29: 보유 카드 중 해당 거래에 적용 가능한 확정 혜택 없음
A30: persona1 | B30: 김서연 | C30: 2026-06 | D30: 2026-06-02T21:50:00 | E30: 이마트 | F30: 마트/쇼핑 | G30: 10600 | H30: 0 | I30: 10600 | J30: 신용카드 | K30: 청춘대로 톡톡카드 | L30: 청춘대로 톡톡카드 | M30: CAP_EXHAUSTED | N30: 0 | O30: 600 | P30: 600 | Q30: 해당 카드의 월 할인 한도가 이미 소진되어 추가 할인을 받지 못함
A31: persona1 | B31: 김서연 | C31: 2026-06 | D31: 2026-06-03T11:35:00 | E31: 메가커피 | F31: 카페/디저트 | G31: 2400 | H31: 200 | I31: 2200 | J31: 신용카드 | K31: 청춘대로 톡톡카드 | L31: 청춘대로 톡톡카드 | M31: BENEFIT_RECEIVED | N31: 200 | O31: 200 | P31: 0
A32: persona1 | B32: 김서연 | C32: 2026-06 | D32: 2026-06-03T19:00:00 | E32: 렌터카 세차비 | F32: 자동차정비 | G32: 22100 | H32: 2100 | I32: 20000 | J32: 신용카드 | K32: 청춘대로 톡톡카드 | L32: 청춘대로 톡톡카드 | M32: BENEFIT_RECEIVED | N32: 2100 | O32: 2100 | P32: 0
A33: persona1 | B33: 김서연 | C33: 2026-06 | D33: 2026-06-04T19:30:00 | E33: 네이버페이 | F33: 간편결제 | G33: 4900 | H33: 500 | I33: 4400 | J33: 신용카드 | K33: 청춘대로 톡톡카드 | L33: 청춘대로 톡톡카드 | M33: BENEFIT_RECEIVED | N33: 500 | O33: 500 | P33: 0
A34: persona1 | B34: 김서연 | C34: 2026-06 | D34: 2026-06-04T23:55:00 | E34: 티머니 | F34: 교통 | G34: 2400 | H34: 0 | I34: 2400 | J34: 체크카드 | K34: 노리2 체크카드(Global) | L34: 청춘대로 톡톡카드 | M34: WRONG_CARD_BEFORE_PICKA | N34: 0 | O34: 100 | P34: 100 | Q34: 픽카 이용 전 다른 카드를 사용하여 받을 수 있었던 혜택을 놓침
A35: persona1 | B35: 김서연 | C35: 2026-06 | D35: 2026-06-05T16:00:00 | E35: 투썸플레이스 | F35: 카페/디저트 | G35: 3600 | H35: 0 | I35: 3600 | J35: 신용카드 | K35: 청춘대로 톡톡카드 | L35: 청춘대로 톡톡카드 | M35: CAP_EXHAUSTED | N35: 0 | O35: 200 | P35: 200 | Q35: 해당 카드의 월 할인 한도가 이미 소진되어 추가 할인을 받지 못함
A36: persona1 | B36: 김서연 | C36: 2026-06 | D36: 2026-06-05T21:40:00 | E36: 인천공항 라운지 | F36: 프리미엄서비스 | G36: 71300 | H36: 0 | I36: 71300 | J36: 신용카드 | K36: 청춘대로 톡톡카드 | M36: NO_ELIGIBLE_BENEFIT | N36: 0 | O36: 0 | P36: 0 | Q36: 보유 카드 중 해당 거래에 적용 가능한 확정 혜택 없음
A37: persona1 | B37: 김서연 | C37: 2026-06 | D37: 2026-06-06T14:30:00 | E37: 필라테스 스튜디오 | F37: 뷰티/피트니스 | G37: 20800 | H37: 0 | I37: 20800 | J37: 신용카드 | K37: 청춘대로 톡톡카드 | L37: 노리2 체크카드(Global) | M37: WRONG_CARD_BEFORE_PICKA | N37: 0 | O37: 1300 | P37: 1300 | Q37: 픽카 이용 전 다른 카드를 사용하여 받을 수 있었던 혜택을 놓침
A38: persona1 | B38: 김서연 | C38: 2026-06 | D38: 2026-06-06T20:10:00 | E38: 한식당 | F38: 외식 | G38: 9000 | H38: 0 | I38: 9000 | J38: 신용카드 | K38: 청춘대로 톡톡카드 | L38: 청춘대로 톡톡카드 | M38: CAP_EXHAUSTED | N38: 0 | O38: 600 | P38: 600 | Q38: 해당 카드의 월 할인 한도가 이미 소진되어 추가 할인을 받지 못함
A39: persona1 | B39: 김서연 | C39: 2026-06 | D39: 2026-06-07T19:35:00 | E39: CU | F39: 편의점 | G39: 3800 | H39: 400 | I39: 3400 | J39: 체크카드 | K39: 노리2 체크카드(Global) | L39: 노리2 체크카드(Global) | M39: BENEFIT_RECEIVED | N39: 400 | O39: 400 | P39: 0
A40: persona1 | B40: 김서연 | C40: 2026-06 | D40: 2026-06-07T21:15:00 | E40: SK텔레콤 | F40: 통신 | G40: 30700 | H40: 3000 | I40: 27700 | J40: 신용카드 | K40: 청춘대로 톡톡카드 | L40: 청춘대로 톡톡카드 | M40: BENEFIT_RECEIVED | N40: 3000 | O40: 3000 | P40: 0
...
